Workbook
Name 振興局: [1]入力欄!$P$3:$S$23

Sheet 入力表
B2: 北海道宿泊税納入申告書・月計表・納入書 入力表
B3: このデータの「入力表」シート及び「月計表」を入力することで、「申告書」、「納入書（領収証書等）」が作成されます。 申告及び納付の際は、「月計表」、「申告書」及び「納入書（領収証書等）」を印刷してお使いください。 各項目の記載方法については別添「宿泊税納入申告書 記載例」をご確認ください。
B4: ※注意事項 ・納入書（領収証書等）の合計額欄を二重線などで訂正すると金融機関で納めることができなくなります。 ・納入書（領収証書等）のシートには、オブジェクトを組み込んでおりますので、必ず表示をして印刷してください。 オブジェクト箇所：上部「公」丸囲み
B6: 申告書提出年月日
B7: 特別徴収義務者 | C7: 住所（所在地）
C8: 氏名（名称）・ 代表者の氏名
B9: 個人番号又は法人番号(最大13桁) | K9: =LEN(D9) -> 0
B10: 宿泊施設 | C10: 宿泊施設所在地
C11: 宿泊施設名
B12: 指定番号（12桁）※必須 | G12: ←北海道から通知した特別徴収義務者登録通知書に記載されている指定番号(徴収原簿番号)を転記してください。
B14: 納入内容 （納入書） | C14: 入力方法 | D14: 月計表・申告書からの転記 | H14: 手入力（納入書（領収証書等）を手入力で作成する場合）
C15: 払込年度 | D15: 令和 | F15: 年度 | H15: 令和 | J15: 年度
C16: 申告対象月 | E16: ～ | I16: ～ | K16: 桁数
C17: 入力例（6月～８月） | D17: ↑2026/6/1 | F17: ↑2026/8/31
C18: 宿泊税額等 | D18: 本税 | E18: =申告書!R28 -> 0 | H18: 本税 | K18: =LEN(E18) -> 1
D19: 延滞金 | H19: 延滞金 | K19: =LEN(E19) -> 0
D20: 過少申告加算金 | H20: 過少申告加算金 | K20: =LEN(E20) -> 0
D21: 不申告加算金 | H21: 不申告加算金 | K21: =LEN(E21) -> 0
D22: 重加算金 | H22: 重加算金 | K22: =LEN(E22) -> 0
D23: 計 | E23: =SUM(E18:F22) -> 0 | H23: 計 | I23: =SUM(I18:J22) -> 0 | K23: =LEN(E23) -> 1
B24: 納期限 | G24: ←2026/9/30（入力例：令和8年6月~8月分の場合)
B25: ・納期限は、3月~5月分は6月末、6月~8月分は9月末、9月~11月分は12月末、12月~2月分は3月末です。 ・9月～11月分の12月末については、法令等に基づき翌年の1月4日が納期限となります。 ・休止・廃業の場合は休止・廃業した日から1ヶ月後が納期限となります。 ・納期限が土日祝日に当たる場合は、その次の平日が納期限となります。

Sheet 月計表①
B2: 指定番号 （徴収原簿番号） | D2: =IF(入力表!D12="","",入力表!D12)
B3: 宿泊施設名 | D3: =IF(入力表!D11="","",入力表!D11)
B5: 令和 | C5: =IF(入力表!D16="","",入力表!D16) | D5: =IF(入力表!D16="","",入力表!D16)
B6: 日付 | C6: 宿泊数（人泊）
C7: 宿泊料金が ２万円未満 | D7: 宿泊料金が２万円 以上５万円未満 | E7: 宿泊料金が ５万円以上 | F7: 課税免除 | G7: 合計
B8: 1 | G8: =IF(COUNT(C8,D8,E8,F8)=0,"",SUM(C8,D8,E8,F8))
B9: 2 | G9: =IF(COUNT(C9,D9,E9,F9)=0,"",SUM(C9,D9,E9,F9))
B10: 3 | G10: =IF(COUNT(C10,D10,E10,F10)=0,"",SUM(C10,D10,E10,F10))
B11: 4 | G11: =IF(COUNT(C11,D11,E11,F11)=0,"",SUM(C11,D11,E11,F11))
B12: 5 | G12: =IF(COUNT(C12,D12,E12,F12)=0,"",SUM(C12,D12,E12,F12))
B13: 6 | G13: =IF(COUNT(C13,D13,E13,F13)=0,"",SUM(C13,D13,E13,F13))
B14: 7 | G14: =IF(COUNT(C14,D14,E14,F14)=0,"",SUM(C14,D14,E14,F14))
B15: 8 | G15: =IF(COUNT(C15,D15,E15,F15)=0,"",SUM(C15,D15,E15,F15))
B16: 9 | G16: =IF(COUNT(C16,D16,E16,F16)=0,"",SUM(C16,D16,E16,F16))
B17: 10 | G17: =IF(COUNT(C17,D17,E17,F17)=0,"",SUM(C17,D17,E17,F17))
B18: 11 | G18: =IF(COUNT(C18,D18,E18,F18)=0,"",SUM(C18,D18,E18,F18))
B19: 12 | G19: =IF(COUNT(C19,D19,E19,F19)=0,"",SUM(C19,D19,E19,F19))
... B38: 31 | G38: =IF(COUNT(C38,D38,E38,F38)=0,"",SUM(C38,D38,E38,F38))
B39: 合計（人泊） | C39: =IF(C7<>"",SUM(C8:C38),"") -> 0 | D39: =IF(D7<>"",SUM(D8:D38),"") -> 0 | E39: =IF(E7<>"",SUM(E8:E38),"") -> 0 | F39: =IF(AND(C5<>"",D5<>""),SUM(F8:F38),"") | G39: =IF(COUNT(C39,D39,E39,F39)=0,"",SUM(C39,D39,E39,F39)) -> 0
B40: 税率（円） | C40: 100 | D40: 200 | E40: 500
B41: 税額（円） | C41: =IFERROR(C39*C40,"") -> 0 | D41: =IFERROR(D39*D40,"") -> 0 | E41: =IFERROR(E39*E40,"") -> 0 | G41: =IF(COUNT(C41,D41,E41)=0,"",SUM(C41,D41,E41)) -> 0

Sheet 月計表②
B2: 指定番号 （徴収原簿番号） | D2: =IF(入力表!D12="","",入力表!D12)
B3: 宿泊施設名 | D3: =IF(入力表!D11="","",入力表!D11)
B5: 令和 | C5: =IF(入力表!D16="","",EDATE(入力表!D16,1)) | D5: =IF(入力表!D16="","",EDATE(入力表!D16,1))
B6: 日付 | C6: 宿泊数（人泊）
C7: 宿泊料金が ２万円未満 | D7: 宿泊料金が２万円 以上５万円未満 | E7: 宿泊料金が ５万円以上 | F7: 課税免除 | G7: 合計
B8: 1 | G8: =IF(COUNT(C8,D8,E8,F8)=0,"",SUM(C8,D8,E8,F8))
B9: 2 | G9: =IF(COUNT(C9,D9,E9,F9)=0,"",SUM(C9,D9,E9,F9))
B10: 3 | G10: =IF(COUNT(C10,D10,E10,F10)=0,"",SUM(C10,D10,E10,F10))
B11: 4 | G11: =IF(COUNT(C11,D11,E11,F11)=0,"",SUM(C11,D11,E11,F11))
B12: 5 | G12: =IF(COUNT(C12,D12,E12,F12)=0,"",SUM(C12,D12,E12,F12))
B13: 6 | G13: =IF(COUNT(C13,D13,E13,F13)=0,"",SUM(C13,D13,E13,F13))
B14: 7 | G14: =IF(COUNT(C14,D14,E14,F14)=0,"",SUM(C14,D14,E14,F14))
B15: 8 | G15: =IF(COUNT(C15,D15,E15,F15)=0,"",SUM(C15,D15,E15,F15))
B16: 9 | G16: =IF(COUNT(C16,D16,E16,F16)=0,"",SUM(C16,D16,E16,F16))
B17: 10 | G17: =IF(COUNT(C17,D17,E17,F17)=0,"",SUM(C17,D17,E17,F17))
B18: 11 | G18: =IF(COUNT(C18,D18,E18,F18)=0,"",SUM(C18,D18,E18,F18))
B19: 12 | G19: =IF(COUNT(C19,D19,E19,F19)=0,"",SUM(C19,D19,E19,F19))
... B38: 31 | G38: =IF(COUNT(C38,D38,E38,F38)=0,"",SUM(C38,D38,E38,F38))
B39: 合計（人泊） | C39: =IF(C7<>"",SUM(C8:C38),"") -> 0 | D39: =IF(D7<>"",SUM(D8:D38),"") -> 0 | E39: =IF(E7<>"",SUM(E8:E38),"") -> 0 | F39: =IF(AND(C5<>"",D5<>""),SUM(F8:F38),"") | G39: =IF(COUNT(C39,D39,E39,F39)=0,"",SUM(C39,D39,E39,F39)) -> 0
B40: 税率（円） | C40: 100 | D40: 200 | E40: 500
B41: 税額（円） | C41: =IFERROR(C39*C40,"") -> 0 | D41: =IFERROR(D39*D40,"") -> 0 | E41: =IFERROR(E39*E40,"") -> 0 | G41: =IF(COUNT(C41,D41,E41)=0,"",SUM(C41,D41,E41)) -> 0

Sheet 月計表③
B2: 指定番号 （徴収原簿番号） | D2: =IF(入力表!D12="","",入力表!D12)
B3: 宿泊施設名 | D3: =IF(入力表!D11="","",入力表!D11)
B5: 令和 | C5: =IF(入力表!D16="","",EDATE(入力表!D16,2)) | D5: =IF(入力表!D16="","",EDATE(入力表!D16,2))
B6: 日付 | C6: 宿泊数（人泊）
C7: 宿泊料金が ２万円未満 | D7: 宿泊料金が２万円 以上５万円未満 | E7: 宿泊料金が ５万円以上 | F7: 課税免除 | G7: 合計
B8: 1 | G8: =IF(COUNT(C8,D8,E8,F8)=0,"",SUM(C8,D8,E8,F8))
B9: 2 | G9: =IF(COUNT(C9,D9,E9,F9)=0,"",SUM(C9,D9,E9,F9))
B10: 3 | G10: =IF(COUNT(C10,D10,E10,F10)=0,"",SUM(C10,D10,E10,F10))
B11: 4 | G11: =IF(COUNT(C11,D11,E11,F11)=0,"",SUM(C11,D11,E11,F11))
B12: 5 | G12: =IF(COUNT(C12,D12,E12,F12)=0,"",SUM(C12,D12,E12,F12))
B13: 6 | G13: =IF(COUNT(C13,D13,E13,F13)=0,"",SUM(C13,D13,E13,F13))
B14: 7 | G14: =IF(COUNT(C14,D14,E14,F14)=0,"",SUM(C14,D14,E14,F14))
B15: 8 | G15: =IF(COUNT(C15,D15,E15,F15)=0,"",SUM(C15,D15,E15,F15))
B16: 9 | G16: =IF(COUNT(C16,D16,E16,F16)=0,"",SUM(C16,D16,E16,F16))
B17: 10 | G17: =IF(COUNT(C17,D17,E17,F17)=0,"",SUM(C17,D17,E17,F17))
B18: 11 | G18: =IF(COUNT(C18,D18,E18,F18)=0,"",SUM(C18,D18,E18,F18))
B19: 12 | G19: =IF(COUNT(C19,D19,E19,F19)=0,"",SUM(C19,D19,E19,F19))
... B38: 31 | G38: =IF(COUNT(C38,D38,E38,F38)=0,"",SUM(C38,D38,E38,F38))
B39: 合計（人泊） | C39: =IF(C7<>"",SUM(C8:C38),"") -> 0 | D39: =IF(D7<>"",SUM(D8:D38),"") -> 0 | E39: =IF(E7<>"",SUM(E8:E38),"") -> 0 | F39: =IF(AND(C5<>"",D5<>""),SUM(F8:F38),"") | G39: =IF(COUNT(C39,D39,E39,F39)=0,"",SUM(C39,D39,E39,F39)) -> 0
B40: 税率（円） | C40: 100 | D40: 200 | E40: 500
B41: 税額（円） | C41: =IFERROR(C39*C40,"") -> 0 | D41: =IFERROR(D39*D40,"") -> 0 | E41: =IFERROR(E39*E40,"") -> 0 | G41: =IF(COUNT(C41,D41,E41)=0,"",SUM(C41,D41,E41)) -> 0

Sheet 申告書
A1: 宿泊税納入申告書
I2: ※処理事項 | J2: 発信年月日 | S2: 徴収原簿番号
J3: 通信日付印 | O3: 確認印
A4: =IF(入力表!D6="","",入力表!D6)
A5: 北海道 札幌道税事務所長 様
A6: 特別徴収 義務者 | C6: 住所（所在地） | I6: =IF(入力表!D7="","",入力表!D7)
C7: 氏名(名称)・代表者の氏名 | I7: =IF(入力表!D8="","",入力表!D8)
C8: 個人番号又は法人番号 | I8: =IF(入力表!$K$9=12,"",MID(入力表!D9,1,1)) | J8: =IF(入力表!$K$9=12,MID(入力表!D9,1,1),MID(入力表!D9,2,1)) | K8: =IF(入力表!$K$9=12,MID(入力表!D9,2,1),MID(入力表!D9,3,1)) | L8: =IF(入力表!$K$9=12,MID(入力表!D9,3,1),MID(入力表!D9,4,1)) | M8: =IF(入力表!$K$9=12,MID(入力表!D9,4,1),MID(入力表!D9,5,1)) | N8: =IF(入力表!$K$9=12,MID(入力表!D9,5,1),MID(入力表!D9,6,1)) | P8: =IF(入力表!$K$9=12,MID(入力表!D9,6,1),MID(入力表!D9,7,1)) | Q8: =IF(入力表!$K$9=12,MID(入力表!D9,7,1),MID(入力表!D9,8,1)) | T8: =IF(入力表!$K$9=12,MID(入力表!D9,8,1),MID(入力表!D9,9,1)) | U8: =IF(入力表!$K$9=12,MID(入力表!D9,9,1),MID(入力表!D9,10,1)) | V8: =IF(入力表!$K$9=12,MID(入力表!D9,10,1),MID(入力表!D9,11,1)) | W8: =IF(入力表!$K$9=12,MID(入力表!D9,11,1),MID(入力表!D9,12,1)) | X8: =IF(入力表!$K$9=12,MID(入力表!D9,12,1),MID(入力表!D9,13,1))
A9: 宿泊 施設 | C9: 所在地 | I9: =IF(入力表!D10="","",入力表!D10)
C10: 名称 | I10: =IF(入力表!D11="","",入力表!D11)
C11: 指定番号 （徴収原簿番号） | I11: =IF(入力表!D12="","",入力表!D12)
A12: 宿 泊 月 | D12: 区 分 | K12: 宿泊数 | N12: 税 率 | R12: 税 額
D13: １人１泊２万円未満 | K13: =月計表①!C39 -> 0 | N13: 100 | R13: =K13*N13 -> 0 | X13: 円
A14: 令和 | B14: =月計表①!C5 | C14: 年 | D14: １人１泊２万円以上５万円未満 | K14: =月計表①!D39 -> 0 | N14: 200 | R14: =K14*N14 -> 0 | X14: 円
D15: １人１泊５万円以上 | K15: =月計表①!E39 -> 0 | N15: 500 | R15: =K15*N15 -> 0 | X15: 円
B16: =月計表①!D5 | C16: 月 | D16: 小 計 | K16: =SUM(K13:M15) -> 0 | R16: =SUM(R13:W15) -> 0 | X16: 円
D17: 課税免除 | K17: =月計表①!F39
D18: １人１泊２万円未満 | K18: =月計表②!C39 -> 0 | N18: 100 | R18: =K18*N18 -> 0 | X18: 円
A19: 令和 | B19: =月計表②!C5 | C19: 年 | D19: １人１泊２万円以上５万円未満 | K19: =月計表②!D39 -> 0 | N19: 200 | R19: =K19*N19 -> 0 | X19: 円
D20: １人１泊５万円以上 | K20: =月計表②!E39 -> 0 | N20: 500 | R20: =K20*N20 -> 0 | X20: 円
B21: =月計表②!D5 | C21: 月 | D21: 小 計 | K21: =SUM(K18:M20) -> 0 | R21: =SUM(R18:W20) -> 0 | X21: 円
D22: 課税免除 | K22: =月計表②!F39
D23: １人１泊２万円未満 | K23: =月計表③!C39 -> 0 | N23: 100 | R23: =K23*N23 -> 0 | X23: 円
A24: 令和 | B24: =月計表③!C5 | C24: 年 | D24: １人１泊２万円以上５万円未満 | K24: =月計表③!D39 -> 0 | N24: 200 | R24: =K24*N24 -> 0 | X24: 円
D25: １人１泊５万円以上 | K25: =月計表③!E39 -> 0 | N25: 500 | R25: =K25*N25 -> 0 | X25: 円
B26: =月計表③!D5 | C26: 月 | D26: 小 計 | K26: =SUM(K23:M25) -> 0 | R26: =SUM(R23:W25) -> 0 | X26: 円
D27: 課税免除 | K27: =月計表③!F39
A28: 合 計 | K28: =IFERROR(K16+K17+K21+K22+K26+K27,"") | R28: =R16+R21+R26 -> 0 | X28: 円
A29: 注意 ※印欄は、記入しないでください。

Sheet 納入書
E2: 道税 | K2: 都道府県コード | P2: 0 | Q2: 1 | R2: 0 | S2: 0 | T2: 0 | U2: 6 | Y2: 領収証書 | BA2: 公
E4: 年度 | K4: 税コード | O4: 期別(申告区分) | X4: 振替口座 | AJ4: 加入者名 | AO4: 北海道会計管理者 | AV4: 取扱庁 | BL4: 事務所 | BP4: 徴収原簿番号 | CF4: 取扱庁リスト
A5: 納税者保存 | E5: =IF(入力表!I15="",入力表!E15,入力表!I15) -> 0 | K5: 26 | O5: =IF(入力表!J16="",入力表!F16,入力表!J16) -> 0 | X5: 02740-9-960011 | AJ5: (札 幌)地区 | AV5: =VLOOKUP(BL5,$CF$5:$CI$27,2,0) -> #N/A | BL5: =ASC(MID(入力表!D12,1,3)) | BP5: =ASC(MID(入力表!D12,4,9)) | CF5: 010 | CG5: 石狩振興局
BB6: 税 目 | BI6: 宿 泊 税 | CF6: 020 | CG6: 渡島総合振興局
BB7: 税 額 | BM7: 千 | BO7: 百 | BQ7: 十 | BS7: 万 | BU7: 千 | BW7: 百 | BY7: 十 | CA7: 円
BL8: =$CJ$31 | BN8: =$CK$31 | BP8: =$CL$31 | BR8: =$CM$31 | BT8: =$CN$31 | BV8: =$CO$31 | BX8: =$CP$31 | BZ8: =$CQ$31 -> 0 | CF8: 030 | CG8: 檜山振興局
BB9: 延滞金額 | BI9: =$CI$33 | BL9: =$CJ$33 | BN9: =$CK$33 | BP9: =$CL$33 | BR9: =$CM$33 | BT9: =$CN$33 | BV9: =$CO$33 | BX9: =$CP$33 | BZ9: =$CQ$33 -> 0 | CF9: 040 | CG9: 後志総合振興局
P10: 住所(所在地) | CF10: 041 | CG10: 小樽道税事務所
R11: =IF(入力表!D7="","",入力表!D7) | BB11: 加算金額 | BD11: 過少申告 | BI11: =$CI$34 | BL11: =$CJ$34 | BN11: =$CK$34 | BP11: =$CL$34 | BR11: =$CM$34 | BT11: =$CN$34 | BV11: =$CO$34 | BX11: =$CP$34 | BZ11: =CQ34 -> 0 | CF11: 050 | CG11: 空知総合振興局
BD12: 不 申 告 | BI12: =$CI$35 | BL12: =$CJ$35 | BN12: =$CK$35 | BP12: =$CL$35 | BR12: =$CM$35 | BT12: =$CN$35 | BV12: =$CO$35 | BX12: =$CP$35 | BZ12: =$CQ$35 -> 0 | CF12: 051 | CG12: 深川道税事務所
E13: 延滞金額計算内訳 | CF13: 060 | CG13: 上川総合振興局
E14: 日 数 | I14: 年率 | L14: 金 額 | BD14: 重 | BI14: =$CI$36 | BL14: =$CJ$36 | BN14: =$CK$36 | BP14: =$CL$36 | BR14: =$CM$36 | BT14: =$CN$36 | BV14: =$CO$36 | BX14: =$CP$36 | BZ14: =$CQ$36 -> 0 | CF14: 061 | CG14: 名寄道税事務所
E15: 日 | I15: % | L15: 円 | CF15: 070 | CG15: 留萌総合振興局
BB16: 合 計 額 | BI16: =$CI$37 | BL16: =$CJ$37 | BN16: =$CK$37 | BP16: =$CL$37 | BR16: =$CM$37 | BT16: =$CN$37 | BV16: =$CO$37 | BX16: =$CP$37 | BZ16: =$CQ$37 -> 0 | CF16: 080 | CG16: 宗谷総合振興局
P17: 氏名(名称) | CF17: 090 | CG17: ｵﾎｰﾂｸ総合振興局
R18: =IF(入力表!D8="","",入力表!D8) | BB18: 納 期 限 | BI18: =IF(入力表!D24="","",入力表!D24) | CF18: 091 | CG18: 北見道税事務所
R19: =IF(入力表!D11="","",入力表!D11) | AX19: 様 | BB19: 納 付 （納 入） 場 所 | BO19: 上記の金額を領収しました。 | CF19: 092 | CG19: 紋別道税事務所
BB20: 北海道指定(収納代理)金融機関 北海道収入取扱員 道内郵便局 | BO20: 領 収 印 | CF20: 100 | CG20: 胆振総合振興局
CF21: 101 | CG21: 苫小牧道税事務所
CF22: 110 | CG22: 日高振興局
E23: ◎裏面も必ずお読みください。 | CF23: 120 | CG23: 十勝総合振興局
CF24: 130 | CG24: 釧路総合振興局
CF25: 140 | CG25: 根室振興局
CF26: 210 | CG26: 札幌道税事務所
CF28: 採用税額 | CH28: 桁数 | CJ28: 千 | CK28: 百 | CL28: 十 | CM28: 万 | CN28: 千 | CO28: 百 | CP28: 十 | CQ28: 円
AU29: ※金融機関には切り離した３枚すべてを提出してください。
AK30: （切り取り線）
CF31: 税額 | CG31: =IF(入力表!I18="",入力表!E18,入力表!I18) -> 0 | CH31: =LEN(CG31) -> 1 | CI31: =IF(AND($CH31<=11,$CH31>=9),MID($CG31,$CH31-8,1),"") | CJ31: =IF(AND($CH31<=11,$CH31>=8),MID($CG31,$CH31-7,1),"") | CK31: =IF(AND($CH$31<=11,$CH$31>=7),MID($CG$31,$CH$31-6,1),"") | CL31: =IF(AND($CH31<=11,$CH31>=6),MID($CG31,$CH31-5,1),"") | CM31: =IF(AND($CH31<=11,$CH31>=5),MID($CG31,$CH31-4,1),"") | CN31: =IF(AND($CH31<=11,$CH31>=4),MID($CG31,$CH31-3,1),"") | CO31: =IF(AND($CH31<=11,$CH31>=3),MID($CG31,$CH31-2,1),"") | CP31: =IF(AND($CH31<=11,$CH31>=2),MID($CG31,$CH31-1,1),"") | CQ31: =IF(AND($CH31<=11,$CH31>=1),MID($CG31,$CH31-0,1),"") -> 0
E33: 道税 | K33: 都道府県コード | P33: 0 | Q33: 1 | R33: 0 | S33: 0 | T33: 0 | U33: 6 | Y33: 収入伝票 | BA33: 公 | CF33: 延滞金 | CG33: =IF(入力表!I19="",入力表!E19,入力表!I19) -> 0 | CH33: =LEN(CG33) -> 1 | CI33: =IF(AND($CH33<=11,$CH33>=9),MID($CG33,$CH33-8,1),"") | CJ33: =IF(AND($CH33<=11,$CH33>=8),MID($CG33,$CH33-7,1),"") | CK33: =IF(AND($CH$33<=11,$CH$33>=7),MID($CG$33,$CH$33-6,1),"") | CL33: =IF(AND($CH33<=11,$CH33>=6),MID($CG33,$CH33-5,1),"") | CM33: =IF(AND($CH33<=11,$CH33>=5),MID($CG33,$CH33-4,1),"") | CN33: =IF(AND($CH33<=11,$CH33>=4),MID($CG33,$CH33-3,1),"") | CO33: =IF(AND($CH33<=11,$CH33>=3),MID($CG33,$CH33-2,1),"") | CP33: =IF(AND($CH33<=11,$CH33>=2),MID($CG33,$CH33-1,1),"") | CQ33: =IF(AND($CH33<=11,$CH33>=1),MID($CG33,$CH33-0,1),"") -> 0
CF34: 過少 | CG34: =IF(入力表!I20="",入力表!E20,入力表!I20) -> 0 | CH34: =LEN(CG34) -> 1 | CI34: =IF(AND($CH34<=11,$CH34>=9),MID($CG34,$CH34-8,1),"") | CJ34: =IF(AND($CH34<=11,$CH34>=8),MID($CG34,$CH34-7,1),"") | CK34: =IF(AND($CH$34<=11,$CH$34>=7),MID($CG$34,$CH$34-6,1),"") | CL34: =IF(AND($CH34<=11,$CH34>=6),MID($CG34,$CH34-5,1),"") | CM34: =IF(AND($CH34<=11,$CH34>=5),MID($CG34,$CH34-4,1),"") | CN34: =IF(AND($CH34<=11,$CH34>=4),MID($CG34,$CH34-3,1),"") | CO34: =IF(AND($CH34<=11,$CH34>=3),MID($CG34,$CH34-2,1),"") | CP34: =IF(AND($CH34<=11,$CH34>=2),MID($CG34,$CH34-1,1),"") | CQ34: =IF(AND($CH34<=11,$CH34>=1),MID($CG34,$CH34-0,1),"") -> 0
E35: 年度 | K35: 税コード | O35: 期別(申告区分) | X35: 振替口座 | AJ35: 加入者名 | AO35: 北海道会計管理者 | AV35: 取扱庁 | BL35: 事務所 | BP35: 徴収原簿番号 | CF35: 不申 | CG35: =IF(入力表!I21="",入力表!E21,入力表!I21) -> 0 | CH35: =LEN(CG35) -> 1 | CI35: =IF(AND($CH35<=11,$CH35>=9),MID($CG35,$CH35-8,1),"") | CJ35: =IF(AND($CH35<=11,$CH35>=8),MID($CG35,$CH35-7,1),"") | CK35: =IF(AND($CH$35<=11,$CH$35>=7),MID($CG$35,$CH$35-6,1),"") | CL35: =IF(AND($CH35<=11,$CH35>=6),MID($CG35,$CH35-5,1),"") | CM35: =IF(AND($CH35<=11,$CH35>=5),MID($CG35,$CH35-4,1),"") | CN35: =IF(AND($CH35<=11,$CH35>=4),MID($CG35,$CH35-3,1),"") | CO35: =IF(AND($CH35<=11,$CH35>=3),MID($CG35,$CH35-2,1),"") | CP35: =IF(AND($CH35<=11,$CH35>=2),MID($CG35,$CH35-1,1),"") | CQ35: =IF(AND($CH35<=11,$CH35>=1),MID($CG35,$CH35-0,1),"") -> 0
A36: 受付局・第一次金融機関保存 | E36: =E5 -> 0 | K36: 26 | O36: =O5 -> 0 | X36: 02740-9-960011 | AJ36: (札 幌)地区 | AV36: =AV5 -> #N/A | BL36: =BL5 | BP36: =BP5 | CF36: 重 | CG36: =IF(入力表!I22="",入力表!E22,入力表!I22) -> 0 | CH36: =LEN(CG36) -> 1 | CI36: =IF(AND($CH36<=11,$CH36>=9),MID($CG36,$CH36-8,1),"") | CJ36: =IF(AND($CH36<=11,$CH36>=8),MID($CG36,$CH36-7,1),"") | CK36: =IF(AND($CH$36<=11,$CH$36>=7),MID($CG$36,$CH$36-6,1),"") | CL36: =IF(AND($CH36<=11,$CH36>=6),MID($CG36,$CH36-5,1),"") | CM36: =IF(AND($CH36<=11,$CH36>=5),MID($CG36,$CH36-4,1),"") | CN36: =IF(AND($CH36<=11,$CH36>=4),MID($CG36,$CH36-3,1),"") | CO36: =IF(AND($CH36<=11,$CH36>=3),MID($CG36,$CH36-2,1),"") | CP36: =IF(AND($CH36<=11,$CH36>=2),MID($CG36,$CH36-1,1),"") | CQ36: =IF(AND($CH36<=11,$CH36>=1),MID($CG36,$CH36-0,1),"") -> 0
P37: とりまとめ金融機関 北海道指定金融機関 北洋銀行 道庁支店 | BB37: 税 目 | BI37: 宿 泊 税 | CF37: 合計 | CG37: =SUM(CG31:CG36) -> 0 | CH37: =LEN(CG37) -> 1 | CI37: =IF(AND($CH37<=11,$CH37>=9),MID($CG37,$CH37-8,1),"") | CJ37: =IF(AND($CH37<=11,$CH37>=8),MID($CG37,$CH37-7,1),"") | CK37: =IF(AND($CH$37<=11,$CH$37>=7),MID($CG$37,$CH$37-6,1),"") | CL37: =IF(AND($CH37<=11,$CH37>=6),MID($CG37,$CH37-5,1),"") | CM37: =IF(AND($CH37<=11,$CH37>=5),MID($CG37,$CH37-4,1),"") | CN37: =IF(AND($CH37<=11,$CH37>=4),MID($CG37,$CH37-3,1),"") | CO37: =IF(AND($CH37<=11,$CH37>=3),MID($CG37,$CH37-2,1),"") | CP37: =IF(AND($CH37<=11,$CH37>=2),MID($CG37,$CH37-1,1),"") | CQ37: =IF(AND($CH37<=11,$CH37>=1),MID($CG37,$CH37-0,1),"") -> 0
BB38: 税 額 | BM38: 千 | BO38: 百 | BQ38: 十 | BS38: 万 | BU38: 千 | BW38: 百 | BY38: 十 | CA38: 円
BI39: =$CI$31 | BL39: =$CJ$31 | BN39: =$CK$31 | BP39: =$CL$31 | BR39: =$CM$31 | BT39: =$CN$31 | BV39: =$CO$31 | BX39: =$CP$31 | BZ39: =$CQ$31 -> 0
BB40: 延滞金額 | BI40: =$CI$33 | BL40: =$CJ$33 | BN40: =$CK$33 | BP40: =$CL$33 | BR40: =$CM$33 | BT40: =$CN$33 | BV40: =$CO$33 | BX40: =$CP$33 | BZ40: =$CQ$33 -> 0
P41: 住所(所在地)
R42: =IF(R11="","",R11) | BB42: 加算金額 | BD42: 過少申告 | BI42: =$CI$34 | BL42: =$CJ$34 | BN42: =$CK$34 | BP42: =$CL$34 | BR42: =$CM$34 | BT42: =$CN$34 | BV42: =$CO$34 | BX42: =$CP$34 | BZ42: =CQ65 -> 0
BD43: 不 申 告 | BI43: =$CI$35 | BL43: =$CJ$35 | BN43: =$CK$35 | BP43: =$CL$35 | BR43: =$CM$35 | BT43: =$CN$35 | BV43: =$CO$35 | BX43: =$CP$35 | BZ43: =$CQ$35 -> 0
BD45: 重 | BI45: =$CI$36 | BL45: =$CJ$36 | BN45: =$CK$36 | BP45: =$CL$36 | BR45: =$CM$36 | BT45: =$CN$36 | BV45: =$CO$36 | BX45: =$CP$36 | BZ45: =$CQ$36 -> 0
...

Sheet ｺｰﾄﾞ一覧（50音順）
A1: 事務所コード一覧（市町村５０音順） | AA1: 「札幌市」と「北海道外」の事務所コードは「２１０」です。
A2: 市町村名 | H2: 事務所 | J2: 市町村名 | Q2: 事務所 | S2: 市町村名 | Z2: 事務所
E3: かな | H3: コード | N3: かな | Q3: コード | W3: かな | Z3: コード
A4: あ | B4: 愛別町 | E4: あいべつちょう | H4: ０６０ | J4: こ | K4: 小清水町 | N4: こしみずちょう | Q4: ０９０ | T4: 南幌町 | W4: なんぽろちょう | Z4: ０５０
B5: 赤井川村 | E5: あかいがわむら | H5: ０４１ | J5: さ | K5: 札幌市 | N5: さっぽろし | Q5: ２１０ | S5: に | T5: 新冠町 | W5: にいかっぷちょう | Z5: １１０
B6: 赤平市 | E6: あかびらし | H6: ０５０ | K6: 様似町 | N6: さまにちょう | Q6: １１０ | T6: 仁木町 | W6: にきちょう | Z6: ０４１
B7: 旭川市 | E7: あさひかわし | H7: ０６０ | K7: 更別村 | N7: さらべつむら | Q7: １２０ | T7: 西興部村 | W7: にしおこっぺむら | Z7: ０９２
B8: 芦別市 | E8: あしべつし | H8: ０５０ | K8: 猿払村 | N8: さるふつむら | Q8: ０８０ | T8: ニセコ町 | W8: にせこちょう | Z8: ０４０
B9: 足寄町 | E9: あしょろちょう | H9: １２０ | K9: 佐呂間町 | N9: さろまちょう | Q9: ０９１ | S9: ぬ | T9: 沼田町 | W9: ぬまたちょう | Z9: ０５１
B10: 厚岸町 | E10: あっけしちょう | H10: １３０ | J10: し | K10: 鹿追町 | N10: しかおいちょう | Q10: １２０ | S10: ね | T10: 根室市 | W10: ねむろし | Z10: １４０
B11: 厚沢部町 | E11: あっさぶちょう | H11: ０３０ | K11: 鹿部町 | N11: しかべちょう | Q11: ０２０ | S11: の | T11: 登別市 | W11: のぼりべつし | Z11: １００
B12: 厚真町 | E12: あつまちょう | H12: １０１ | K12: 標茶町 | N12: しべちゃちょう | Q12: １３０ | S12: は | T12: 函館市 | W12: はこだてし | Z12: ０２０
B13: 網走市 | E13: あばしりし | H13: ０９０ | K13: 士別市 | N13: しべつし | Q13: ０６１ | T13: 羽幌町 | W13: はぼろちょう | Z13: ０７０
B14: 安平町 | E14: あびらちょう | H14: １０１ | K14: 標津町 | N14: しべつちょう | Q14: １４０ | T14: 浜頓別町 | W14: はまとんべつちょう | Z14: ０８０
A15: い | B15: 池田町 | E15: いけだちょう | H15: １２０ | K15: 士幌町 | N15: しほろちょう | Q15: １２０ | T15: 浜中町 | W15: はまなかちょう | Z15: １３０
B16: 石狩市 | E16: いしかりし | H16: ０１０ | K16: 島牧村 | N16: しままきむら | Q16: ０４０ | S16: ひ | T16: 美瑛町 | W16: びえいちょう | Z16: ０６０
B17: 今金町 | E17: いまかねちょう | H17: ０３０ | K17: 清水町 | N17: しみずちょう | Q17: １２０ | T17: 東神楽町 | W17: ひがしかぐらちょう | Z17: ０６０
B18: 岩内町 | E18: いわないちょう | H18: ０４０ | K18: 占冠村 | N18: しむかっぷむら | Q18: ０６０ | T18: 東川町 | W18: ひがしかわちょう | Z18: ０６０
B19: 岩見沢市 | E19: いわみざわし | H19: ０５０ | K19: 下川町 | N19: しもかわちょう | Q19: ０６１ | T19: 日高町 | W19: ひだかちょう | Z19: １１０
A20: う | B20: 歌志内市 | E20: うたしないし | H20: ０５０ | K20: 積丹町 | N20: しゃこたんちょう | Q20: ０４１ | T20: 比布町 | W20: ぴっぷちょう | Z20: ０６０
B21: 浦臼町 | E21: うらうすちょう | H21: ０５０ | K21: 斜里町 | N21: しゃりちょう | Q21: ０９０ | T21: 美唄市 | W21: びばいし | Z21: ０５０
B22: 浦河町 | E22: うらかわちょう | H22: １１０ | K22: 初山別村 | N22: しょさんべつむら | Q22: ０７０ | T22: 美深町 | W22: びふかちょう | Z22: ０６１
B23: 浦幌町 | E23: うらほろちょう | H23: １２０ | K23: 白老町 | N23: しらおいちょう | Q23: １０１ | T23: 美幌町 | W23: びほろちょう | Z23: ０９０
B24: 雨竜町 | E24: うりゅうちょう | H24: ０５１ | K24: 白糠町 | N24: しらぬかちょう | Q24: １３０ | T24: 平取町 | W24: びらとりちょう | Z24: １１０
A25: え | B25: 江差町 | E25: えさしちょう | H25: ０３０ | K25: 知内町 | N25: しりうちちょう | Q25: ０２０ | T25: 広尾町 | W25: ひろおちょう | Z25: １２０
B26: 枝幸町 | E26: えさしちょう | H26: ０８０ | K26: 新篠津村 | N26: しんしのつむら | Q26: ０１０ | S26: ふ | T26: 深川市 | W26: ふかがわし | Z26: ０５１
B27: 恵庭市 | E27: えにわし | H27: ０１０ | K27: 新得町 | N27: しんとくちょう | Q27: １２０ | T27: 福島町 | W27: ふくしまちょう | Z27: ０２０
B28: 江別市 | E28: えべつし | H28: ０１０ | K28: 新十津川町 | N28: しんとつかわちょう | Q28: ０５０ | T28: 富良野市 | W28: ふらのし | Z28: ０６０
B29: えりも町 | E29: えりもちょう | H29: １１０ | K29: 新ひだか町 | N29: しんひだかちょう | Q29: １１０ | T29: 古平町 | W29: ふるびらちょう | Z29: ０４１
B30: 遠軽町 | E30: えんがるちょう | H30: ０９１ | J30: す | K30: 寿都町 | N30: すっつちょう | Q30: ０４０ | S30: へ | T30: 別海町 | W30: べつかいちょう | Z30: １４０
B31: 遠別町 | E31: えんべつちょう | H31: ０７０ | K31: 砂川市 | N31: すながわし | Q31: ０５０ | S31: ほ | T31: 北斗市 | W31: ほくとし | Z31: ０２０
A32: お | B32: 雄武町 | E32: おうむちょう | H32: ０９２ | J32: せ | K32: せたな町 | N32: せたなちょう | Q32: ０３０ | T32: 北竜町 | W32: ほくりゅうちょう | Z32: ０５１
B33: 大空町 | E33: おおぞらちょう | H33: ０９０ | J33: そ | K33: 壮瞥町 | N33: そうべつちょう | Q33: １００ | T33: 幌加内町 | W33: ほろかないちょう | Z33: ０６０
B34: 奥尻町 | E34: おくしりちょう | H34: ０３０ | J34: た | K34: 大樹町 | N34: たいきちょう | Q34: １２０ | T34: 幌延町 | W34: ほろのべちょう | Z34: ０８０
B35: 置戸町 | E35: おけとちょう | H35: ０９１ | K35: 鷹栖町 | N35: たかすちょう | Q35: ０６０ | T35: 本別町 | W35: ほんべつちょう | Z35: １２０
B36: 興部町 | E36: おこっぺちょう | H36: ０９２ | K36: 滝川市 | N36: たきかわし | Q36: ０５０ | S36: ま | T36: 幕別町 | W36: まくべつちょう | Z36: １２０
B37: 長万部町 | E37: おしゃまんべちょう | H37: ０２０ | K37: 滝上町 | N37: たきのうえちょう | Q37: ０９２ | T37: 増毛町 | W37: ましけちょう | Z37: ０７０
B38: 小樽市 | E38: おたるし | H38: ０４１ | K38: 伊達市 | N38: だてし | Q38: １００ | T38: 真狩村 | W38: まっかりむら | Z38: ０４０
B39: 音威子府村 | E39: おといねっぷむら | H39: ０６１ | J39: ち | K39: 秩父別町 | N39: ちっぷべつちょう | Q39: ０５１ | T39: 松前町 | W39: まつまえちょう | Z39: ０２０
B40: 音更町 | E40: おとふけちょう | H40: １２０ | K40: 千歳市 | N40: ちとせし | Q40: ０１０ | S40: み | T40: 三笠市 | W40: みかさし | Z40: ０５０
...

Sheet ｺｰﾄﾞ一覧（ｺｰﾄﾞ順）
A1: 事務所コード一覧（コード順）
A2: 事務所 コード | B2: 事務所名 | C2: 市町村名
A3: ２１０ | B3: 札幌道税事務所 | C3: 札幌市、北海道外
A4: ０１０ | B4: 石狩振興局 | C4: 江別市、千歳市、恵庭市、北広島市、石狩市、当別町、新篠津村
A5: ０２０ | B5: 渡島総合振興局 | C5: 函館市、北斗市、松前町、福島町、知内町、木古内町、七飯町、鹿部町、森町、八雲町、長万部町
A6: ０３０ | B6: 檜山振興局 | C6: 江差町、上ノ国町、厚沢部町、乙部町、奥尻町、今金町、せたな町
A7: ０４０ | B7: 後志総合振興局 | C7: 島牧村、寿都町、黒松内町、蘭越町、ニセコ町、真狩村、留寿都村、喜茂別町、京極町、倶知安町、
C8: 共和町、岩内町、泊村、神恵内村
A9: ０４１ | B9: 小樽道税事務所 | C9: 小樽市、積丹町、古平町、仁木町、余市町、赤井川村
A10: ０５０ | B10: 空知総合振興局 | C10: 夕張市、岩見沢市、美唄市、芦別市、赤平市、三笠市、滝川市、砂川市、歌志内市、南幌町、
C11: 奈井江町、上砂川町、由仁町、長沼町、栗山町、月形町、浦臼町、新十津川町
A12: ０５１ | B12: 深川道税事務所 | C12: 深川市、妹背牛町、秩父別町、雨竜町、北竜町、沼田町
A13: ０６０ | B13: 上川総合振興局 | C13: 旭川市、富良野市、鷹栖町、東神楽町、当麻町、比布町、愛別町、上川町、東川町、美瑛町、
C14: 上富良野町、中富良野町、南富良野町、占冠村、幌加内町
A15: ０６１ | B15: 名寄道税事務所 | C15: 士別市、名寄市、和寒町、剣淵町、下川町、美深町、音威子府村、中川町
A16: ０７０ | B16: 留萌振興局 | C16: 留萌市、増毛町、小平町、苫前町、羽幌町、初山別村、遠別町、天塩町
A17: ０８０ | B17: 宗谷総合振興局 | C17: 稚内市、猿払村、浜頓別町、中頓別町、枝幸町、豊富町、礼文町、利尻町、利尻富士町、幌延町
A18: ０９０ | B18: オホーツク総合振興局 | C18: 網走市、大空町、美幌町、津別町、斜里町、清里町、小清水町
A19: ０９１ | B19: 北見道税事務所 | C19: 北見市、訓子府町、置戸町、佐呂間町、遠軽町
A20: ０９２ | B20: 紋別道税事務所 | C20: 紋別市、湧別町、滝上町、興部町、西興部村、雄武町
A21: １００ | B21: 胆振総合振興局 | C21: 室蘭市、登別市、伊達市、豊浦町、壮瞥町、洞爺湖町
A22: １０１ | B22: 苫小牧道税事務所 | C22: 苫小牧市、白老町、厚真町、安平町、むかわ町
A23: １１０ | B23: 日高振興局 | C23: 日高町、平取町、新冠町、浦河町、様似町、えりも町、新ひだか町
A24: １２０ | B24: 十勝総合振興局 | C24: 帯広市、音更町、士幌町、上士幌町、鹿追町、新得町、清水町、芽室町、中札内村、更別村、大樹町、
C25: 広尾町、幕別町、池田町、豊頃町、本別町、足寄町、陸別町、浦幌町
A26: １３０ | B26: 釧路総合振興局 | C26: 釧路市、釧路町、厚岸町、浜中町、標茶町、弟子屈町、鶴居村、白糠町
A27: １４０ | B27: 根室振興局 | C27: 根室市、別海町、中標津町､標津町、羅臼町
